ERROR:asyncio:Future exception was never retrieved
future: <Future finished exception=StreamClosedError('Stream is closed',)>
Traceback (most recent call last):
  File "/usr/local/lib/python3.6/site-packages/tornado/gen.py", line 1141, in run
    yielded = self.gen.throw(*exc_info)
  File "/usr/local/lib/python3.6/site-packages/tornado_mysql/connections.py", line 631, in close_async
    yield self._stream.write(send_data)
  File "/usr/local/lib/python3.6/site-packages/tornado/gen.py", line 1133, in run
    value = future.result()
tornado.iostream.StreamClosedError: Stream is closed
